Workbook

Sheet README
A1: ISV AI Use Case Assessment 入力テンプレート
A2: お客様がAIユースケース・事業/サービス情報をExcelで入力し、Oracle側でAI Use Case Assessmentに利用するためのワークブックです。
A4: 項目 | B4: 内容 | C4: 補足
A5: 目的 | B5: 自社SaaS/パッケージ、保有IP、業務データ、競合差別化、AIで実現したい機能を整理し、AIユースケース評価、OCI構成検討、PoC計画、レポート作成に活用します。 | C5: 入力フォームの回答欄に記入してください。
A6: 入力対象 | B6: 会社・事業概要、Assessment対象範囲、製品・サービス情報、顧客・価格・競合、データ/IP、AIで実現したいこと、AIユースケース候補、技術/OCI、セキュリティ、PoC条件。 | C6: HTMLフォームおよびMicrosoft Forms設計書の10セクションをExcel化しています。
A7: 入力ルール | B7: 水色セルが入力欄です。必須項目はオレンジ表示です。選択式の項目にはプルダウンを設定しています。複数選択の場合は「;」区切りで記入できます。 | C7: 例：SaaS;パッケージ;保守/運用支援
A8: 機密情報 | B8: 個人情報、顧客機密データ、本番データは、Oracle担当者と合意した範囲・手順に従ってください。Excel添付時は提出資料名/リンクのみ記載する運用を推奨します。 | C8: 本テンプレートはアセスメント事前整理用です。
A9: 提出方法 | B9: 入力後、ExcelファイルをSharePoint/Teams/メール等でOracle担当者へ共有してください。必要に応じて「登録用_縦持ち」シートをSharePoint List登録に利用できます。 | C9: SharePoint登録列はForms設計書に合わせています。
A10: 利用シート | B10: ダッシュボード：入力進捗確認。入力フォーム：お客様記入欄。登録用_縦持ち：システム連携/登録用。入力例_エクス：サンプル。選択肢一覧：プルダウン元。Sources：出典。 | C10: 顧客に入力していただく主シートは「入力フォーム」です。

Sheet ダッシュボード
A1: 入力進捗ダッシュボード
A2: 必須項目の入力状況と、セクション別の完了状況を確認できます。
A4: サマリー
A5: 必須項目数 | B5: =COUNTIF('入力フォーム'!C:C,"必須")
A6: 必須入力済 | B6: =COUNTIFS('入力フォーム'!C:C,"必須",'入力フォーム'!E:E,"<>")
A7: 必須未入力 | B7: =B5-B6
A8: 必須入力率 | B8: =IF(B5=0,0,B6/B5)
A9: 任意入力済 | B9: =COUNTIFS('入力フォーム'!C:C,"任意",'入力フォーム'!E:E,"<>")
A12: セクションNo | B12: セクション名 | C12: 必須項目数 | D12: 必須入力済 | E12: 未入力 | F12: 入力率 | G12: 確認ポイント
A13: 0 | B13: 入力前の確認 | C13: =COUNTIFS('入力フォーム'!A:A,A13,'入力フォーム'!C:C,"必須") | D13: =COUNTIFS('入力フォーム'!A:A,A13,'入力フォーム'!C:C,"必須",'入力フォーム'!E:E,"<>") | E13: =C13-D13 | F13: =IF(C13=0,"-",D13/C13) | G13: 未入力がある場合は「入力フォーム」シートの赤/オレンジ表示セルを確認
A14: 1 | B14: 会社・回答者情報 | C14: =COUNTIFS('入力フォーム'!A:A,A14,'入力フォーム'!C:C,"必須") | D14: =COUNTIFS('入力フォーム'!A:A,A14,'入力フォーム'!C:C,"必須",'入力フォーム'!E:E,"<>") | E14: =C14-D14 | F14: =IF(C14=0,"-",D14/C14) | G14: 未入力がある場合は「入力フォーム」シートの赤/オレンジ表示セルを確認
A15: 2 | B15: Assessment対象範囲 | C15: =COUNTIFS('入力フォーム'!A:A,A15,'入力フォーム'!C:C,"必須") | D15: =COUNTIFS('入力フォーム'!A:A,A15,'入力フォーム'!C:C,"必須",'入力フォーム'!E:E,"<>") | E15: =C15-D15 | F15: =IF(C15=0,"-",D15/C15) | G15: 未入力がある場合は「入力フォーム」シートの赤/オレンジ表示セルを確認
A16: 3 | B16: 製品・サービス情報 / ISVアセット・IP | C16: =COUNTIFS('入力フォーム'!A:A,A16,'入力フォーム'!C:C,"必須") | D16: =COUNTIFS('入力フォーム'!A:A,A16,'入力フォーム'!C:C,"必須",'入力フォーム'!E:E,"<>") | E16: =C16-D16 | F16: =IF(C16=0,"-",D16/C16) | G16: 未入力がある場合は「入力フォーム」シートの赤/オレンジ表示セルを確認
A17: 4 | B17: 顧客・価格・競合 | C17: =COUNTIFS('入力フォーム'!A:A,A17,'入力フォーム'!C:C,"必須") | D17: =COUNTIFS('入力フォーム'!A:A,A17,'入力フォーム'!C:C,"必須",'入力フォーム'!E:E,"<>") | E17: =C17-D17 | F17: =IF(C17=0,"-",D17/C17) | G17: 未入力がある場合は「入力フォーム」シートの赤/オレンジ表示セルを確認
A18: 5 | B18: データ/IP・利用条件 | C18: =COUNTIFS('入力フォーム'!A:A,A18,'入力フォーム'!C:C,"必須") | D18: =COUNTIFS('入力フォーム'!A:A,A18,'入力フォーム'!C:C,"必須",'入力フォーム'!E:E,"<>") | E18: =C18-D18 | F18: =IF(C18=0,"-",D18/C18) | G18: 未入力がある場合は「入力フォーム」シートの赤/オレンジ表示セルを確認
A19: 6 | B19: AIで実現したいこと | C19: =COUNTIFS('入力フォーム'!A:A,A19,'入力フォーム'!C:C,"必須") | D19: =COUNTIFS('入力フォーム'!A:A,A19,'入力フォーム'!C:C,"必須",'入力フォーム'!E:E,"<>") | E19: =C19-D19 | F19: =IF(C19=0,"-",D19/C19) | G19: 未入力がある場合は「入力フォーム」シートの赤/オレンジ表示セルを確認
A20: 7 | B20: AIユースケース候補 | C20: =COUNTIFS('入力フォーム'!A:A,A20,'入力フォーム'!C:C,"必須") | D20: =COUNTIFS('入力フォーム'!A:A,A20,'入力フォーム'!C:C,"必須",'入力フォーム'!E:E,"<>") | E20: =C20-D20 | F20: =IF(C20=0,"-",D20/C20) | G20: 未入力がある場合は「入力フォーム」シートの赤/オレンジ表示セルを確認
A21: 8 | B21: 技術・OCI期待範囲 | C21: =COUNTIFS('入力フォーム'!A:A,A21,'入力フォーム'!C:C,"必須") | D21: =COUNTIFS('入力フォーム'!A:A,A21,'入力フォーム'!C:C,"必須",'入力フォーム'!E:E,"<>") | E21: =C21-D21 | F21: =IF(C21=0,"-",D21/C21) | G21: 未入力がある場合は「入力フォーム」シートの赤/オレンジ表示セルを確認
A22: 9 | B22: セキュリティ / ガバナンス | C22: =COUNTIFS('入力フォーム'!A:A,A22,'入力フォーム'!C:C,"必須") | D22: =COUNTIFS('入力フォーム'!A:A,A22,'入力フォーム'!C:C,"必須",'入力フォーム'!E:E,"<>") | E22: =C22-D22 | F22: =IF(C22=0,"-",D22/C22) | G22: 未入力がある場合は「入力フォーム」シートの赤/オレンジ表示セルを確認
A23: 10 | B23: PoC・評価条件・提出資料 | C23: =COUNTIFS('入力フォーム'!A:A,A23,'入力フォーム'!C:C,"必須") | D23: =COUNTIFS('入力フォーム'!A:A,A23,'入力フォーム'!C:C,"必須",'入力フォーム'!E:E,"<>") | E23: =C23-D23 | F23: =IF(C23=0,"-",D23/C23) | G23: 未入力がある場合は「入力フォーム」シートの赤/オレンジ表示セルを確認
A26: 次アクション
A27: 1. 「入力フォーム」シートの水色セルに記入してください。
A28: 2. 必須入力率が100%になったら、必要に応じて提出予定資料名/リンクを記入してください。
A29: 3. Oracle担当者は「登録用_縦持ち」シートをSharePoint List登録/レポート生成用に利用できます。

Sheet 入力フォーム
A1: ISV AI Use Case Assessment 入力フォーム
A2: 水色セルに回答を入力してください。必須項目は未入力時に赤/オレンジで表示されます。複数選択は「;」区切りで記入できます。
A3: 注意：個人情報、顧客機密データ、本番データは、Oracle担当者と合意した範囲・手順に従ってください。添付ファイルは原則としてファイル名/SharePointリンクのみを記載してください。
A5: セクションNo | B5: 質問ID | C5: 必須 | D5: 設問 | E5: 回答入力欄（お客様記入） | F5: 入力ガイド/例 | G5: 入力例（エクス） | H5: 設問タイプ | I5: 選択肢/尺度 | J5: SharePoint列名 | K5: 入力状況
A6: 0. 入力前の確認
A7: 0 | B7: F001 | C7: 必須 | D7: 情報利用目的を確認しましたか？ | F7: 本フォームは、ISV AI Use Case Assessmentの事前整理、AIユースケース評価、OCI構成検討、PoC計画、レポート作成に利用します。 | H7: Choice（単一選択） | I7: 確認しました | J7: ConsentPurpose | K7: =IF($B7="","",IF($C7="必須",IF(LEN(TRIM($E7))>0,"OK","未入力"),IF(LEN(TRIM($E7))>0,"入力済","任意")))
A8: 0 | B8: F002 | C8: 必須 | D8: 本番データ・顧客機密データ・個人情報をアップロードしないことを確認しましたか？ | F8: 添付資料は、Oracle担当者と合意した範囲の資料に限定してください。 | H8: Choice（単一選択） | I8: 確認しました | J8: ConsentNoSensitiveUpload | K8: =IF($B8="","",IF($C8="必須",IF(LEN(TRIM($E8))>0,"OK","未入力"),IF(LEN(TRIM($E8))>0,"入力済","任意")))
A9: 1. 会社・回答者情報
A10: 1 | B10: F101 | C10: 必須 | D10: 会社名 | F10: 例：株式会社〇〇 | G10: 株式会社エクス | H10: Text（短い回答） | J10: CompanyName | K10: =IF($B10="","",IF($C10="必須",IF(LEN(TRIM($E10))>0,"OK","未入力"),IF(LEN(TRIM($E10))>0,"入力済","任意")))
A11: 1 | B11: F102 | C11: 任意 | D11: 会社URL | F11: 例：https://www.example.co.jp/ | G11: https://www.xeex.co.jp/ | H11: Text（短い回答） | J11: CompanyURL | K11: =IF($B11="","",IF($C11="必須",IF(LEN(TRIM($E11))>0,"OK","未入力"),IF(LEN(TRIM($E11))>0,"入力済","任意")))
A12: 1 | B12: F103 | C12: 必須 | D12: 事業概要 | F12: 製品単体ではなく、周辺サービス、導入支援、運用支援も含めて記入してください。 | G12: 製造業向けの生産管理パッケージを中核に、製造業向けクラウドサービス/プラットフォーム、DX関連サービス、導入コンサルティング、カスタマイズ開発、稼働支援、保守を提供するソフトウェアベンダー。 | H12: Text（長い回答） | J12: BusinessOverview | K12: =IF($B12="","",IF($C12="必須",IF(LEN(TRIM($E12))>0,"OK","未入力"),IF(LEN(TRIM($E12))>0,"入力済","任意")))
A13: 1 | B13: F104 | C13: 必須 | D13: 主な顧客像 | F13: 例：中堅・中小製造業、従業員100〜3,000名、工場/生産管理部門/購買部門 | G13: 中堅・中小の製造業。生産管理、購買、在庫、現場、販売管理などの部門が主な利用者。 | H13: Text（長い回答） | J13: MainCustomers | K13: =IF($B13="","",IF($C13="必須",IF(LEN(TRIM($E13))>0,"OK","未入力"),IF(LEN(TRIM($E13))>0,"入力済","任意")))
A14: 1 | B14: F105 | C14: 任意 | D14: 対象業種・業態 | F14: 複数選択可。その他の場合は自由記述を併用してください。 | G14: 製造業;生産管理;販売管理;サプライチェーン;調達・購買 | H14: Choice（複数選択） | I14: 製造業;流通/小売;金融;医療/ヘルスケア;公共;建設;バックオフィス;物流/SCM;教育;不動産;その他 | J14: IndustrySegments | K14: =IF($B14="","",IF($C14="必須",IF(LEN(TRIM($E14))>0,"OK","未入力"),IF(LEN(TRIM($E14))>0,"入力済","任意")))
A15: 1 | B15: F106 | C15: 任意 | D15: 自社の強み・保有IP | F15: 例：業界特化の業務ロジック、マスタ管理、導入ノウハウ、既存顧客データ、テンプレート | G15: 生産・販売統合型の業務ロジック、製造業向けマスタ/実績データ、導入実績、周辺DXソリューションとの接続可能性。 | H15: Text（長い回答） | J15: BusinessStrengthIP | K15: =IF($B15="","",IF($C15="必須",IF(LEN(TRIM($E15))>0,"OK","未入力"),IF(LEN(TRIM($E15))>0,"入力済","任意")))
A16: 1 | B16: F107 | C16: 必須 | D16: 入力者氏名 | F16: 例：山田 太郎 | H16: Text（短い回答） | J16: RespondentName | K16: =IF($B16="","",IF($C16="必須",IF(LEN(TRIM($E16))>0,"OK","未入力"),IF(LEN(TRIM($E16))>0,"入力済","任意")))
A17: 1 | B17: F108 | C17: 必須 | D17: 入力者メール | F17: 例：name@example.co.jp | H17: Text（短い回答） | J17: RespondentEmail | K17: =IF($B17="","",IF($C17="必須",IF(LEN(TRIM($E17))>0,"OK","未入力"),IF(LEN(TRIM($E17))>0,"入力済","任意")))
A18: 1 | B18: F109 | C18: 任意 | D18: 入力者所属/役職 | F18: 例：CTO、プロダクト責任者、開発責任者、営業責任者 | H18: Text（短い回答） | J18: RespondentRole | K18: =IF($B18="","",IF($C18="必須",IF(LEN(TRIM($E18))>0,"OK","未入力"),IF(LEN(TRIM($E18))>0,"入力済","任意")))
A19: 2. Assessment対象範囲
A20: 2 | B20: F201 | C20: 必須 | D20: 今回のAssessment対象範囲 | F20: 既存サービスに加え、本番環境構築中・開発中・構想中の新サービスも対象にできます。 | H20: Choice（複数選択） | I20: 既存SaaS/クラウドサービス;既存パッケージ;新規サービス/新規SaaS;本番環境構築中;開発中;構想中;複数プロジェクト横断 | J20: AssessmentScope | K20: =IF($B20="","",IF($C20="必須",IF(LEN(TRIM($E20))>0,"OK","未入力"),IF(LEN(TRIM($E20))>0,"入力済","任意")))
A21: 2 | B21: F202 | C21: 任意 | D21: 対象プロジェクト数 | F21: Microsoft Formsでは最大3件分の入力欄を用意しています。3件超の場合は補足欄に記入してください。 | H21: Choice（単一選択） | I21: 1件;2件;3件以上;未定 | J21: ProjectCount | K21: =IF($B21="","",IF($C21="必須",IF(LEN(TRIM($E21))>0,"OK","未入力"),IF(LEN(TRIM($E21))>0,"入力済","任意")))
A22: 2 | B22: F211 | C22: 必須 | D22: プロジェクト1：プロジェクト/製品名 | F22: 例：既存SaaS、構築中サービス、開発中プロダクト | G22: Factory-ONE 電脳工場 データ活用 | H22: Text（短い回答） | J22: Project1Name | K22: =IF($B22="","",IF($C22="必須",IF(LEN(TRIM($E22))>0,"OK","未入力"),IF(LEN(TRIM($E22))>0,"入力済","任意")))
A23: 2 | B23: F212 | C23: 必須 | D23: プロジェクト1：段階 | F23: 現在の開発/運用段階を選択してください。 | G23: 本番運用中 | H23: Choice（単一選択） | I23: 本番運用中;本番環境構築中;開発中;構想中;PoC中;未定 | J23: Project1Stage | K23: =IF($B23="","",IF($C23="必須",IF(LEN(TRIM($E23))>0,"OK","未入力"),IF(LEN(TRIM($E23))>0,"入力済","任意")))
A24: 2 | B24: F213 | C24: 必須 | D24: プロジェクト1：優先度 | F24: 現時点の優先度で構いません。 | G24: 高 | H24: Choice（単一選択） | I24: 高;中;低;未定 | J24: Project1Priority | K24: =IF($B24="","",IF($C24="必須",IF(LEN(TRIM($E24))>0,"OK","未入力"),IF(LEN(TRIM($E24))>0,"入力済","任意")))
A25: 2 | B25: F214 | C25: 必須 | D25: プロジェクト1：AI活用の狙い・確認したいこと | F25: 例：データ活用、AI機能を初期リリースに含めるか、運用データ蓄積後に段階導入するか | G25: 既存データを活用し、需給・在庫、生産計画、原価・調達のAIユースケースを検討する。 | H25: Text（長い回答） | J25: Project1AIIntent | K25: =IF($B25="","",IF($C25="必須",IF(LEN(TRIM($E25))>0,"OK","未入力"),IF(LEN(TRIM($E25))>0,"入力済","任意")))
A26: 2 | B26: F221 | C26: 任意 | D26: プロジェクト2：プロジェクト/製品名 | F26: 例：既存SaaS、構築中サービス、開発中プロダクト | G26: こうばWith | H26: Text（短い回答） | J26: Project2Name | K26: =IF($B26="","",IF($C26="必須",IF(LEN(TRIM($E26))>0,"OK","未入力"),IF(LEN(TRIM($E26))>0,"入力済","任意")))
A27: 2 | B27: F222 | C27: 任意 | D27: プロジェクト2：段階 | F27: 現在の開発/運用段階を選択してください。 | G27: 本番環境構築中 | H27: Choice（単一選択） | I27: 本番運用中;本番環境構築中;開発中;構想中;PoC中;未定 | J27: Project2Stage | K27: =IF($B27="","",IF($C27="必須",IF(LEN(TRIM($E27))>0,"OK","未入力"),IF(LEN(TRIM($E27))>0,"入力済","任意")))
A28: 2 | B28: F223 | C28: 任意 | D28: プロジェクト2：優先度 | F28: 現時点の優先度で構いません。 | G28: 中 | H28: Choice（単一選択） | I28: 高;中;低;未定 | J28: Project2Priority | K28: =IF($B28="","",IF($C28="必須",IF(LEN(TRIM($E28))>0,"OK","未入力"),IF(LEN(TRIM($E28))>0,"入力済","任意")))
A29: 2 | B29: F224 | C29: 任意 | D29: プロジェクト2：AI活用の狙い・確認したいこと | F29: 例：データ活用、AI機能を初期リリースに含めるか、運用データ蓄積後に段階導入するか | G29: 本番データの種類、保持場所、テナント構成、運用監視、AI機能の段階導入可否を確認する。 | H29: Text（長い回答） | J29: Project2AIIntent | K29: =IF($B29="","",IF($C29="必須",IF(LEN(TRIM($E29))>0,"OK","未入力"),IF(LEN(TRIM($E29))>0,"入力済","任意")))
A30: 2 | B30: F231 | C30: 任意 | D30: プロジェクト3：プロジェクト/製品名 | F30: 例：既存SaaS、構築中サービス、開発中プロダクト | G30: Endeval（旧Endevor） | H30: Text（短い回答） | J30: Project3Name | K30: =IF($B30="","",IF($C30="必須",IF(LEN(TRIM($E30))>0,"OK","未入力"),IF(LEN(TRIM($E30))>0,"入力済","任意")))
A31: 2 | B31: F232 | C31: 任意 | D31: プロジェクト3：段階 | F31: 現在の開発/運用段階を選択してください。 | G31: 開発中 | H31: Choice（単一選択） | I31: 本番運用中;本番環境構築中;開発中;構想中;PoC中;未定 | J31: Project3Stage | K31: =IF($B31="","",IF($C31="必須",IF(LEN(TRIM($E31))>0,"OK","未入力"),IF(LEN(TRIM($E31))>0,"入力済","任意")))
A32: 2 | B32: F233 | C32: 任意 | D32: プロジェクト3：優先度 | F32: 現時点の優先度で構いません。 | G32: 中 | H32: Choice（単一選択） | I32: 高;中;低;未定 | J32: Project3Priority | K32: =IF($B32="","",IF($C32="必須",IF(LEN(TRIM($E32))>0,"OK","未入力"),IF(LEN(TRIM($E32))>0,"入力済","任意")))
A33: 2 | B33: F234 | C33: 任意 | D33: プロジェクト3：AI活用の狙い・確認したいこと | F33: 例：データ活用、AI機能を初期リリースに含めるか、運用データ蓄積後に段階導入するか | G33: 構成検討中のため、事業目的、対象業務、アーキテクチャ、AI活用の狙いを整理する。 | H33: Text（長い回答） | J33: Project3AIIntent | K33: =IF($B33="","",IF($C33="必須",IF(LEN(TRIM($E33))>0,"OK","未入力"),IF(LEN(TRIM($E33))>0,"入力済","任意")))
A34: 3. 製品・サービス情報 / ISVアセット・IP
A35: 3 | B35: F301 | C35: 必須 | D35: 主対象製品/サービス名 | F35: 例：生産管理SaaS、EDIサービス、グループウェア、周辺ソリューション | G35: Factory-ONE 電脳工場 | H35: Text（短い回答） | J35: PrimaryProductName | K35: =IF($B35="","",IF($C35="必須",IF(LEN(TRIM($E35))>0,"OK","未入力"),IF(LEN(TRIM($E35))>0,"入力済","任意")))
A36: 3 | B36: F302 | C36: 任意 | D36: 提供形態 | F36: 複数選択可。 | G36: パッケージ;クラウドサービス | H36: Choice（複数選択） | I36: SaaS;パッケージ;オンプレミス;クラウドサービス;プラットフォーム;導入支援/コンサル;保守/運用支援;その他 | J36: DeliveryModel | K36: =IF($B36="","",IF($C36="必須",IF(LEN(TRIM($E36))>0,"OK","未入力"),IF(LEN(TRIM($E36))>0,"入力済","任意")))
A37: 3 | B37: F303 | C37: 任意 | D37: 位置づけ・提供価値 | F37: 例：中堅・中小製造業向けの生産・販売統合型システム | G37: 中堅・中小製造業向けの生産・販売統合型の生産管理システム。 | H37: Text（長い回答） | J37: ProductPositioning | K37: =IF($B37="","",IF($C37="必須",IF(LEN(TRIM($E37))>0,"OK","未入力"),IF(LEN(TRIM($E37))>0,"入力済","任意")))
A38: 3 | B38: F304 | C38: 必須 | D38: 代表的な機能・業務範囲 | F38: 例：受注、出荷、生産計画、発注、受入、在庫、進捗、原価、請求 | G38: 生産計画、受注・出荷、手配計画、発注、受入、在庫、負荷、進捗、原価、請求、売掛、入金、仕入、買掛、支払。 | H38: Text（長い回答） | J38: ProductFunctions | K38: =IF($B38="","",IF($C38="必須",IF(LEN(TRIM($E38))>0,"OK","未入力"),IF(LEN(TRIM($E38))>0,"入力済","任意")))
A39: 3 | B39: F305 | C39: 必須 | D39: 関連データ領域 | F39: 例：マスタ、実績、履歴、文書、外部データ、取引先データ | G39: 品目、BOM、取引先、工程などのマスタ、受注/生産/在庫/購買/原価などの実績、納期変更履歴、EDI受注取込。 | H39: Text（長い回答） | J39: DataDomains | K39: =IF($B39="","",IF($C39="必須",IF(LEN(TRIM($E39))>0,"OK","未入力"),IF(LEN(TRIM($E39))>0,"入力済","任意")))
A40: 3 | B40: F306 | C40: 任意 | D40: 関連/拡張ソリューション | F40: 例：在庫診断、価格シミュレータ、現品照合、帳票、スケジューラ | G40: EX在庫診断/EX在庫シミュレータ、EX調達価格シミュレータ、EXQR現品照合。 | H40: Text（長い回答） | J40: RelatedSolutions | K40: =IF($B40="","",IF($C40="必須",IF(LEN(TRIM($E40))>0,"OK","未入力"),IF(LEN(TRIM($E40))>0,"入力済","任意")))
A41: 3 | B41: F307 | C41: 任意 | D41: カスタマイズ/個社対応の状況 | F41: 例：ソース公開、個社カスタマイズあり、共通機能化可能な範囲 | G41: パッケージでありつつソース公開を行い、利用企業側でのカスタマイズも可能。共通AI機能と個社固有拡張の切り分けが必要。 | H41: Text（長い回答） | J41: CustomizationStatus | K41: =IF($B41="","",IF($C41="必須",IF(LEN(TRIM($E41))>0,"OK","未入力"),IF(LEN(TRIM($E41))>0,"入力済","任意")))
...

Sheet 登録用_縦持ち
A1: 登録用_縦持ち
A2: 「入力フォーム」シートの回答を質問ID単位で参照する登録用テーブルです。SharePoint Listや後続処理への取り込みに利用できます。
A4: 表示順 | B4: セクションNo | C4: セクション名 | D4: 質問ID | E4: 設問 | F4: SharePoint列名 | G4: 必須 | H4: 回答値
A5: 1 | B5: 0 | C5: 入力前の確認 | D5: F001 | E5: 情報利用目的を確認しましたか？ | F5: ConsentPurpose | G5: 必須 | H5: ='入力フォーム'!E7
A6: 2 | B6: 0 | C6: 入力前の確認 | D6: F002 | E6: 本番データ・顧客機密データ・個人情報をアップロードしないことを確認しましたか？ | F6: ConsentNoSensitiveUpload | G6: 必須 | H6: ='入力フォーム'!E8
A7: 3 | B7: 1 | C7: 会社・回答者情報 | D7: F101 | E7: 会社名 | F7: CompanyName | G7: 必須 | H7: ='入力フォーム'!E10
A8: 4 | B8: 1 | C8: 会社・回答者情報 | D8: F102 | E8: 会社URL | F8: CompanyURL | G8: 任意 | H8: ='入力フォーム'!E11
A9: 5 | B9: 1 | C9: 会社・回答者情報 | D9: F103 | E9: 事業概要 | F9: BusinessOverview | G9: 必須 | H9: ='入力フォーム'!E12
A10: 6 | B10: 1 | C10: 会社・回答者情報 | D10: F104 | E10: 主な顧客像 | F10: MainCustomers | G10: 必須 | H10: ='入力フォーム'!E13
A11: 7 | B11: 1 | C11: 会社・回答者情報 | D11: F105 | E11: 対象業種・業態 | F11: IndustrySegments | G11: 任意 | H11: ='入力フォーム'!E14
A12: 8 | B12: 1 | C12: 会社・回答者情報 | D12: F106 | E12: 自社の強み・保有IP | F12: BusinessStrengthIP | G12: 任意 | H12: ='入力フォーム'!E15
A13: 9 | B13: 1 | C13: 会社・回答者情報 | D13: F107 | E13: 入力者氏名 | F13: RespondentName | G13: 必須 | H13: ='入力フォーム'!E16
A14: 10 | B14: 1 | C14: 会社・回答者情報 | D14: F108 | E14: 入力者メール | F14: RespondentEmail | G14: 必須 | H14: ='入力フォーム'!E17
A15: 11 | B15: 1 | C15: 会社・回答者情報 | D15: F109 | E15: 入力者所属/役職 | F15: RespondentRole | G15: 任意 | H15: ='入力フォーム'!E18
A16: 12 | B16: 2 | C16: Assessment対象範囲 | D16: F201 | E16: 今回のAssessment対象範囲 | F16: AssessmentScope | G16: 必須 | H16: ='入力フォーム'!E20
A17: 13 | B17: 2 | C17: Assessment対象範囲 | D17: F202 | E17: 対象プロジェクト数 | F17: ProjectCount | G17: 任意 | H17: ='入力フォーム'!E21
A18: 14 | B18: 2 | C18: Assessment対象範囲 | D18: F211 | E18: プロジェクト1：プロジェクト/製品名 | F18: Project1Name | G18: 必須 | H18: ='入力フォーム'!E22
A19: 15 | B19: 2 | C19: Assessment対象範囲 | D19: F212 | E19: プロジェクト1：段階 | F19: Project1Stage | G19: 必須 | H19: ='入力フォーム'!E23
A20: 16 | B20: 2 | C20: Assessment対象範囲 | D20: F213 | E20: プロジェクト1：優先度 | F20: Project1Priority | G20: 必須 | H20: ='入力フォーム'!E24
A21: 17 | B21: 2 | C21: Assessment対象範囲 | D21: F214 | E21: プロジェクト1：AI活用の狙い・確認したいこと | F21: Project1AIIntent | G21: 必須 | H21: ='入力フォーム'!E25
A22: 18 | B22: 2 | C22: Assessment対象範囲 | D22: F221 | E22: プロジェクト2：プロジェクト/製品名 | F22: Project2Name | G22: 任意 | H22: ='入力フォーム'!E26
A23: 19 | B23: 2 | C23: Assessment対象範囲 | D23: F222 | E23: プロジェクト2：段階 | F23: Project2Stage | G23: 任意 | H23: ='入力フォーム'!E27
A24: 20 | B24: 2 | C24: Assessment対象範囲 | D24: F223 | E24: プロジェクト2：優先度 | F24: Project2Priority | G24: 任意 | H24: ='入力フォーム'!E28
A25: 21 | B25: 2 | C25: Assessment対象範囲 | D25: F224 | E25: プロジェクト2：AI活用の狙い・確認したいこと | F25: Project2AIIntent | G25: 任意 | H25: ='入力フォーム'!E29
A26: 22 | B26: 2 | C26: Assessment対象範囲 | D26: F231 | E26: プロジェクト3：プロジェクト/製品名 | F26: Project3Name | G26: 任意 | H26: ='入力フォーム'!E30
A27: 23 | B27: 2 | C27: Assessment対象範囲 | D27: F232 | E27: プロジェクト3：段階 | F27: Project3Stage | G27: 任意 | H27: ='入力フォーム'!E31
... A29: 25 | B29: 2 | C29: Assessment対象範囲 | D29: F234 | E29: プロジェクト3：AI活用の狙い・確認したいこと | F29: Project3AIIntent | G29: 任意 | H29: ='入力フォーム'!E33
A30: 26 | B30: 3 | C30: 製品・サービス情報 / ISVアセット・IP | D30: F301 | E30: 主対象製品/サービス名 | F30: PrimaryProductName | G30: 必須 | H30: ='入力フォーム'!E35
A31: 27 | B31: 3 | C31: 製品・サービス情報 / ISVアセット・IP | D31: F302 | E31: 提供形態 | F31: DeliveryModel | G31: 任意 | H31: ='入力フォーム'!E36
A32: 28 | B32: 3 | C32: 製品・サービス情報 / ISVアセット・IP | D32: F303 | E32: 位置づけ・提供価値 | F32: ProductPositioning | G32: 任意 | H32: ='入力フォーム'!E37
A33: 29 | B33: 3 | C33: 製品・サービス情報 / ISVアセット・IP | D33: F304 | E33: 代表的な機能・業務範囲 | F33: ProductFunctions | G33: 必須 | H33: ='入力フォーム'!E38
A34: 30 | B34: 3 | C34: 製品・サービス情報 / ISVアセット・IP | D34: F305 | E34: 関連データ領域 | F34: DataDomains | G34: 必須 | H34: ='入力フォーム'!E39
A35: 31 | B35: 3 | C35: 製品・サービス情報 / ISVアセット・IP | D35: F306 | E35: 関連/拡張ソリューション | F35: RelatedSolutions | G35: 任意 | H35: ='入力フォーム'!E40
A36: 32 | B36: 3 | C36: 製品・サービス情報 / ISVアセット・IP | D36: F307 | E36: カスタマイズ/個社対応の状況 | F36: CustomizationStatus | G36: 任意 | H36: ='入力フォーム'!E41
A37: 33 | B37: 3 | C37: 製品・サービス情報 / ISVアセット・IP | D37: F308 | E37: 追加対象製品・サービスがあれば記入してください | F37: AdditionalProducts | G37: 任意 | H37: ='入力フォーム'!E42
A38: 34 | B38: 4 | C38: 顧客・価格・競合 | D38: F401 | E38: ターゲット顧客規模 | F38: CustomerScale | G38: 任意 | H38: ='入力フォーム'!E44
A39: 35 | B39: 4 | C39: 顧客・価格・競合 | D39: F402 | E39: 価格形態 | F39: PricingModel | G39: 任意 | H39: ='入力フォーム'!E45
A40: 36 | B40: 4 | C40: 顧客・価格・競合 | D40: F403 | E40: ライセンス形式 | F40: LicenseModel | G40: 任意 | H40: ='入力フォーム'!E46
A41: 37 | B41: 4 | C41: 顧客・価格・競合 | D41: F404 | E41: 現行収益モデル | F41: CurrentRevenueModel | G41: 任意 | H41: ='入力フォーム'!E47
A42: 38 | B42: 4 | C42: 顧客・価格・競合 | D42: F405 | E42: AI機能の想定収益モデル | F42: AIRevenueModel | G42: 任意 | H42: ='入力フォーム'!E48
...

Sheet 入力例_エクス
A1: 入力例_エクス
A2: service_input.txtの内容をもとにした入力例です。実際の回答は各社の状況に合わせて変更してください。
A4: 質問ID | B4: 設問 | C4: 入力例 | D4: 出典メモ
A5: F001 | B5: 情報利用目的を確認しましたか？
A6: F002 | B6: 本番データ・顧客機密データ・個人情報をアップロードしないことを確認しましたか？
A7: F101 | B7: 会社名 | C7: 株式会社エクス | D7: service_input.txt / HTMLフォームのサンプル値を要約
A8: F102 | B8: 会社URL | C8: https://www.xeex.co.jp/ | D8: service_input.txt / HTMLフォームのサンプル値を要約
A9: F103 | B9: 事業概要 | C9: 製造業向けの生産管理パッケージを中核に、製造業向けクラウドサービス/プラットフォーム、DX関連サービス、導入コンサルティング、カスタマイズ開発、稼働支援、保守を提供するソフトウェアベンダー。 | D9: service_input.txt / HTMLフォームのサンプル値を要約
A10: F104 | B10: 主な顧客像 | C10: 中堅・中小の製造業。生産管理、購買、在庫、現場、販売管理などの部門が主な利用者。 | D10: service_input.txt / HTMLフォームのサンプル値を要約
A11: F105 | B11: 対象業種・業態 | C11: 製造業;生産管理;販売管理;サプライチェーン;調達・購買 | D11: service_input.txt / HTMLフォームのサンプル値を要約
A12: F106 | B12: 自社の強み・保有IP | C12: 生産・販売統合型の業務ロジック、製造業向けマスタ/実績データ、導入実績、周辺DXソリューションとの接続可能性。 | D12: service_input.txt / HTMLフォームのサンプル値を要約
A13: F107 | B13: 入力者氏名
A14: F108 | B14: 入力者メール
A15: F109 | B15: 入力者所属/役職
A16: F201 | B16: 今回のAssessment対象範囲
A17: F202 | B17: 対象プロジェクト数
A18: F211 | B18: プロジェクト1：プロジェクト/製品名 | C18: Factory-ONE 電脳工場 データ活用 | D18: service_input.txt / HTMLフォームのサンプル値を要約
A19: F212 | B19: プロジェクト1：段階 | C19: 本番運用中 | D19: service_input.txt / HTMLフォームのサンプル値を要約
A20: F213 | B20: プロジェクト1：優先度 | C20: 高 | D20: service_input.txt / HTMLフォームのサンプル値を要約
A21: F214 | B21: プロジェクト1：AI活用の狙い・確認したいこと | C21: 既存データを活用し、需給・在庫、生産計画、原価・調達のAIユースケースを検討する。 | D21: service_input.txt / HTMLフォームのサンプル値を要約
A22: F221 | B22: プロジェクト2：プロジェクト/製品名 | C22: こうばWith | D22: service_input.txt / HTMLフォームのサンプル値を要約
A23: F222 | B23: プロジェクト2：段階 | C23: 本番環境構築中 | D23: service_input.txt / HTMLフォームのサンプル値を要約
A24: F223 | B24: プロジェクト2：優先度 | C24: 中 | D24: service_input.txt / HTMLフォームのサンプル値を要約
A25: F224 | B25: プロジェクト2：AI活用の狙い・確認したいこと | C25: 本番データの種類、保持場所、テナント構成、運用監視、AI機能の段階導入可否を確認する。 | D25: service_input.txt / HTMLフォームのサンプル値を要約
A26: F231 | B26: プロジェクト3：プロジェクト/製品名 | C26: Endeval（旧Endevor） | D26: service_input.txt / HTMLフォームのサンプル値を要約
A27: F232 | B27: プロジェクト3：段階 | C27: 開発中 | D27: service_input.txt / HTMLフォームのサンプル値を要約
A28: F233 | B28: プロジェクト3：優先度 | C28: 中 | D28: service_input.txt / HTMLフォームのサンプル値を要約
A29: F234 | B29: プロジェクト3：AI活用の狙い・確認したいこと | C29: 構成検討中のため、事業目的、対象業務、アーキテクチャ、AI活用の狙いを整理する。 | D29: service_input.txt / HTMLフォームのサンプル値を要約
... A39: F402 | B39: 価格形態 | C39: 月額サブスクリプション;保守費;個別見積 | D39: service_input.txt / HTMLフォームのサンプル値を要約
A40: F403 | B40: ライセンス形式
A41: F404 | B41: 現行収益モデル | C41: パッケージ/クラウド利用料、導入コンサルティング、カスタマイズ開発、稼働支援、保守。 | D41: service_input.txt / HTMLフォームのサンプル値を要約
A42: F405 | B42: AI機能の想定収益モデル | C42: AIアドオン;上位プラン;AI Agent実行回数課金;標準機能化による解約率低減 | D42: service_input.txt / HTMLフォームのサンプル値を要約
A43: F406 | B43: 主な競合製品・競合企業 | C43: 同業生産管理パッケージ、ERP、製造業向けSaaS、内製システム。詳細は顧客ヒアリングで確認。 | D43: service_input.txt / HTMLフォームのサンプル値を要約
A44: F407 | B44: 競合と比較したAI差別化仮説 | C44: 生産管理・販売管理・EDI・現場帳票などのデータを横断し、需要予測、納期遅延予兆、在庫リスク、調達価格影響を説明できるAI機能を提供することで差別化する仮説。 | D44: service_input.txt / HTMLフォームのサンプル値を要約
A45: F408 | B45: 市場投入上の課題・懸念
A46: F501 | B46: 保有データ・業務IP | C46: 品目マスタ、BOM、取引先、工程、受注、出荷、生産計画、発注、受入、在庫、負荷、進捗、原価、請求、売掛、入金、仕入、買掛、支払、EDI取引、現場帳票、問い合わせ/マニュアル。 | D46: service_input.txt / HTMLフォームのサンプル値を要約
A47: F502 | B47: データ種別 | C47: マスタデータ;トランザクション;文書/PDF/マニュアル;外部データ/API;複数企業間データ | D47: service_input.txt / HTMLフォームのサンプル値を要約
A48: F503 | B48: データの所在・保持場所 | C48: 自社SaaS DB;顧客環境;外部基幹システム;EDI/外部取引基盤;ファイル/文書ストレージ | D48: service_input.txt / HTMLフォームのサンプル値を要約
A49: F504 | B49: データ形式・連携方式 | C49: RDB;CSV;API;EDI;PDF/文書;画像/帳票 | D49: service_input.txt / HTMLフォームのサンプル値を要約
A50: F505 | B50: データ量・更新頻度・品質 | C50: データ量、履歴期間、欠損、表記揺れ、マスタ整備状況、更新頻度は初回ヒアリングで確認。 | D50: service_input.txt / HTMLフォームのサンプル値を要約
...

Sheet 選択肢一覧
A1: 選択肢一覧
A2: 入力フォームのプルダウンに利用する選択肢です。複数選択項目はフォーム上で「;」区切りで入力可能です。
A4: F001 | B4: F002 | C4: F105 | D4: F201 | E4: F202 | F4: F212 | G4: F213 | H4: F222 | I4: F223 | J4: F232 | K4: F233 | L4: F302 | M4: F401 | N4: F402 | O4: F403 | P4: F405 | Q4: F502 | R4: F503 | S4: F504 | T4: F509_1 | U4: F509_2 | V4: F509_3 | W4: F509_4 | X4: F509_5 | Y4: F509_6 | Z4: F601 | AA4: F603 | AB4: F604 | AC4: F607 | AD4: F712 | AE4: F713 | AF4: F716 | AG4: F722 | AH4: F723 | AI4: F726 | AJ4: F732 | AK4: F733 | AL4: F736 | AM4: F802 | AN4: F803 | AO4: F805 | AP4: F901 | AQ4: F905 | AR4: F906 | AS4: F1003 | AT4: F1006 | AU4: F1007 | AV4: F1010
A5: 情報利用目的を確認しましたか？ | B5: 本番データ・顧客機密データ・個人情報をアップロードしないことを確認しましたか？ | C5: 対象業種・業態 | D5: 今回のAssessment対象範囲 | E5: 対象プロジェクト数 | F5: プロジェクト1：段階 | G5: プロジェクト1：優先度 | H5: プロジェクト2：段階 | I5: プロジェクト2：優先度 | J5: プロジェクト3：段階 | K5: プロジェクト3：優先度 | L5: 提供形態 | M5: ターゲット顧客規模 | N5: 価格形態 | O5: ライセンス形式 | P5: AI機能の想定収益モデル | Q5: データ種別 | R5: データの所在・保持場所 | S5: データ形式・連携方式 | T5: データ成熟度：必要データが存在する | U5: データ成熟度：データ項目定義が明確 | V5: データ成熟度：データ品質を把握している | W5: データ成熟度：顧客データ利用許諾が整理済み | X5: データ成熟度：匿名化・マスキング方針がある | Y5: データ成熟度：API・連携方式がある | Z5: AI活用目的 | AA5: 期待するAI機能・サービス内容 | AB5: AIの実行レベル | AC5: AI機能の想定利用者 | AD5: ユースケース1：業務領域 | AE5: ユースケース1：優先度 | AF5: ユースケース1：想定AI技術 | AG5: ユースケース2：業務領域 | AH5: ユースケース2：優先度 | AI5: ユースケース2：想定AI技術 | AJ5: ユースケース3：業務領域 | AK5: ユースケース3：優先度 | AL5: ユースケース3：想定AI技術 | AM5: 利用中クラウド/基盤 | AN5: 利用中DB/データ基盤 | AO5: OCI上で求める範囲 | AP5: セキュリティ要件 | AQ5: 本番データ利用可能性 | AR5: 生成AI利用に関する社内承認状況 | AS5: 希望スケジュール | AT5: アセスメント後に希望する次アクション | AU5: 提出予定資料 | AV5: 入力内容のOracle担当者・事務局への共有可否
A6: 確認しました | B6: 確認しました | C6: 製造業 | D6: 既存SaaS/クラウドサービス | E6: 1件 | F6: 本番運用中 | G6: 高 | H6: 本番運用中 | I6: 高 | J6: 本番運用中 | K6: 高 | L6: SaaS | M6: SMB | N6: 月額サブスクリプション | O6: Named User | P6: AIアドオン | Q6: マスタデータ | R6: 自社SaaS DB | S6: RDB | T6: 未整理 | U6: 未整理 | V6: 未整理 | W6: 未整理 | X6: 未整理 | Y6: 未整理 | Z6: 新サービス開発・収益増 | AA6: RAG/ナレッジ検索 | AB6: 説明/回答のみ | AC6: エンドユーザー | AD6: 需給・在庫 | AE6: 高 | AF6: 生成AI | AG6: 需給・在庫 | AH6: 高 | AI6: 生成AI | AJ6: 需給・在庫 | AK6: 高 | AL6: 生成AI | AM6: AWS | AN6: Oracle Database | AO6: データ基盤 | AP6: テナント分離 | AQ6: 利用不可 | AR6: 承認済み | AS6: 1ヶ月以内 | AT6: AI Use Case Assessment実施 | AU6: 製品紹介資料 | AV6: 共有可
C7: 流通/小売 | D7: 既存パッケージ | E7: 2件 | F7: 本番環境構築中 | G7: 中 | H7: 本番環境構築中 | I7: 中 | J7: 本番環境構築中 | K7: 中 | L7: パッケージ | M7: 中堅企業 | N7: 年額サブスクリプション | O7: Concurrent User | P7: 上位プラン | Q7: トランザクション | R7: 顧客環境 | S7: CSV | T7: 一部整理 | U7: 一部整理 | V7: 一部整理 | W7: 一部整理 | X7: 一部整理 | Y7: 一部整理 | Z7: 競合差別化 | AA7: 自然言語でのデータ問い合わせ | AB7: 提案・推奨まで | AC7: 管理者 | AD7: 生産計画・進捗 | AE7: 中 | AF7: RAG | AG7: 生産計画・進捗 | AH7: 中 | AI7: RAG | AJ7: 生産計画・進捗 | AK7: 中 | AL7: RAG | AM7: Azure | AN7: PostgreSQL | AO7: 生成AI | AP7: 暗号化 | AQ7: 匿名化データのみ可 | AR7: 条件付き承認 | AS7: 3ヶ月以内 | AT7: RAG/Agent PoC | AU7: 画面キャプチャ | AV7: 個別範囲を相談
C8: 金融 | D8: 新規サービス/新規SaaS | E8: 3件以上 | F8: 開発中 | G8: 低 | H8: 開発中 | I8: 低 | J8: 開発中 | K8: 低 | L8: オンプレミス | M8: 大企業 | N8: ユーザー課金 | O8: Site License | P8: 利用量課金 | Q8: 文書/PDF/マニュアル | R8: 外部基幹システム | S8: API | T8: 整理済み | U8: 整理済み | V8: 整理済み | W8: 整理済み | X8: 整理済み | Y8: 整理済み | Z8: 業務効率化・運用効率化 | AA8: 要約 | AB8: 人間承認後に実行 | AC8: 経営/管理職 | AD8: 原価・調達 | AE8: 低 | AF8: Vector Search | AG8: 原価・調達 | AH8: 低 | AI8: Vector Search | AJ8: 原価・調達 | AK8: 低 | AL8: Vector Search | AM8: Google Cloud | AN8: MySQL | AO8: RAG | AP8: アクセス制御 | AQ8: サンプルデータのみ可 | AR8: 申請中 | AS8: 6ヶ月以内 | AT8: AI Database検証 | AU8: API仕様 | AV8: 共有不可
C9: 医療/ヘルスケア | D9: 本番環境構築中 | E9: 未定 | F9: 構想中 | G9: 未定 | H9: 構想中 | I9: 未定 | J9: 構想中 | K9: 未定 | L9: クラウドサービス | M9: エンタープライズ | N9: テナント課金 | O9: Tenant License | P9: AI Agent実行回数課金 | Q9: ログ/利用履歴 | R9: ファイル/文書ストレージ | S9: EDI | T9: 検証済み | U9: 検証済み | V9: 検証済み | W9: 検証済み | X9: 検証済み | Y9: 検証済み | Z9: 顧客体験向上 | AA9: 文書/帳票生成 | AB9: 条件付きで自動実行 | AC9: サポート担当 | AD9: 業務支援 | AE9: 未定 | AF9: AI Agent | AG9: 業務支援 | AH9: 未定 | AI9: AI Agent | AJ9: 業務支援 | AK9: 未定 | AL9: AI Agent | AM9: OCI | AN9: SQL Server | AO9: AI Agent | AP9: 監査ログ | AQ9: 条件付きで本番データ可 | AR9: 未承認 | AS9: FY内 | AT9: OCI移行/コスト相談 | AU9: データ項目一覧
C10: 公共 | D10: 開発中 | F10: PoC中 | H10: PoC中 | J10: PoC中 | L10: プラットフォーム | M10: 公共 | N10: API/利用量課金 | O10: Device/拠点課金 | P10: 帳票/文書処理件数課金 | Q10: 画像/図面/帳票 | R10: DWH/Datamart | S10: PDF/文書 | T10: 不明 | U10: 不明 | V10: 不明 | W10: 不明 | X10: 不明 | Y10: 不明 | Z10: 従業員体験向上 | AA10: 予測 | AB10: 完全自動実行を検討 | AC10: 開発/運用担当 | AD10: サプライチェーン | AF10: 自然言語SQL/NL2SQL | AG10: サプライチェーン | AI10: 自然言語SQL/NL2SQL | AJ10: サプライチェーン | AL10: 自然言語SQL/NL2SQL | AM10: オンプレミス | AN10: NoSQL | AO10: Vector Search | AP10: ネットワーク分離 | AQ10: 個別合意後に判断 | AR10: 未確認 | AS10: 未定 | AT10: セキュリティ相談 | AU10: 業務フロー
C11: 建設 | D11: 構想中 | F11: 未定 | H11: 未定 | J11: 未定 | L11: 導入支援/コンサル | M11: 海外 | N11: 初期費用 | O11: API Call | P11: 成果/業務KPI連動 | Q11: 音声/会話 | R11: Object Storage | S11: 画像/帳票 | Z11: コスト/原価率改善 | AA11: 異常検知 | AB11: 未定 | AC11: 顧客企業のIT部門 | AD11: 製品開発・運用 | AF11: 予測/時系列分析 | AG11: 製品開発・運用 | AI11: 予測/時系列分析 | AJ11: 製品開発・運用 | AL11: 予測/時系列分析 | AM11: 自社DC | AN11: DWH | AO11: アプリ連携 | AP11: キー管理 | AQ11: 未定 | AT11: 共同GTM/Marketplace検討 | AU11: システム構成図
C12: バックオフィス | D12: 複数プロジェクト横断 | L12: 保守/運用支援 | M12: 未定 | N12: 保守費 | O12: Transaction | P12: 標準機能化による解約率低減 | Q12: 外部データ/API | R12: EDI/外部取引基盤 | S12: ログ | Z12: リスク低減・品質向上 | AA12: 最適化/推薦 | AC12: 取引先/サプライヤー | AD12: カスタマーサポート | AF12: 異常検知 | AG12: カスタマーサポート | AI12: 異常検知 | AJ12: カスタマーサポート | AL12: 異常検知 | AM12: SaaS/PaaS | AN12: Data Lake | AO12: セキュリティ | AP12: データ保管場所 | AT12: 未定 | AU12: FAQ
C13: 物流/SCM | L13: その他 | N13: ライセンス買い切り | O13: その他 | P13: 未定 | Q13: 複数企業間データ | R13: 未定 | S13: 音声 | Z13: 開発生産性向上 | AA13: 画像・帳票認識 | AC13: その他 | AD13: セキュリティ | AF13: 最適化 | AG13: セキュリティ | AI13: 最適化 | AJ13: セキュリティ | AL13: 最適化 | AM13: 未定/非公開 | AN13: Search Engine | AO13: 監視・運用 | AP13: 脆弱性管理 | AU13: マニュアル
C14: 教育 | N14: 個別見積 | Q14: 個人情報/機密情報を含む | S14: その他 | AA14: 音声/議事録 | AD14: その他 | AF14: 画像認識 | AG14: その他 | AI14: 画像認識 | AJ14: その他 | AL14: 画像認識 | AN14: その他 | AO14: 移行/マルチクラウド | AP14: プロンプト/入力制御 | AU14: サンプルデータ
C15: 不動産 | AA15: AI Agentによる業務実行支援 | AF15: 文書理解/OCR | AI15: 文書理解/OCR | AL15: 文書理解/OCR | AO15: PoC環境 | AP15: 出力フィルタリング | AU15: なし/後日
C16: その他 | AA16: コード/開発支援 | AF16: 音声認識 | AI16: 音声認識 | AL16: 音声認識 | AO16: 未定
AA17: 運用監視 | AF17: データ可視化 | AI17: データ可視化 | AL17: データ可視化
AF18: Human-in-the-loop | AI18: Human-in-the-loop | AL18: Human-in-the-loop

Sheet Sources
A1: Sources
A2: 本ワークブックで参照したファイル・資料です。スプレッドシート内ではURL/ファイルパスをプレーンテキストで記載しています。
A4: 区分 | B4: 資料/ページ | C4: URL/ファイル | D4: 用途
A5: Uploaded file | B5: service_input.txt | C5: /mnt/data/service_input.txt | D5: 株式会社エクスのサンプル内容、製品/サービス、AI論点、ヒアリング項目の元資料
A6: Uploaded/generated file | B6: isv_ai_use_case_assessment_input_form.html | C6: /mnt/data/isv_ai_use_case_assessment_input_form.html | D6: HTMLフォームの10セクション・項目構成・サンプル値
A7: Generated file | B7: ISV_AI_Use_Case_Assessment_MSForms_Format.xlsx | C7: /mnt/data/ISV_AI_Use_Case_Assessment_MSForms_Format.xlsx | D7: Microsoft Forms設計書、SharePoint列定義、設問定義
A8: Microsoft Support | B8: Microsoft Formsでフォームを作成 | C8: https://support.microsoft.com/ja-jp/forms/create-a-form-with-microsoft-forms | D8: Forms設問タイプ/セクション化の参考
A9: Microsoft Support | B9: SharePoint WebパーツでMicrosoft Formsを利用 | C9: https://support.microsoft.com/ja-jp/forms/use-the-microsoft-forms-web-part-on-a-sharepoint-site | D9: SharePoint共有/埋め込みの参考
A10: Microsoft Support | B10: Power AutomateでMicrosoft Forms回答を処理 | C10: https://support.microsoft.com/ja-jp/forms/create-an-automated-workflow-for-microsoft-forms | D10: SharePoint List登録フローの参考
